Workbook

Sheet PRICING PLANTILLA
C1: Herramienta Pricing | P1: Código: | Q1: FO - FI - 03
P2: Versión: | Q2: 1
P3: Fecha de emisión: | Q3: 44171
B5: *Todos los meses cambiar el # de personas actuales - Ojo! | E5: Comisión Venta | F5: =I5*C17 -> 107310 | G5: Jugar con Gross Margin | H5: PV COP | I5: =+((C12+C8+C10)/(1-F6-'Parámetros'!L8*C18))+'Parámetros'!L9*C18 -> 1073100
E6: Gross Margin | F6: 0.5 | H6: PV USD | I6: =I5/'Parámetros'!L3 -> 302.28169
B7: Resumen | E7: Imp. Renta | F7: =(I5-F5-C12)*'Parámetros'!L6 -> 0 | H7: Horas | I7: 180
B8: Costo Equipo | C8: =G20 -> 0 | E8: ICA | F8: =I5*'Parámetros'!L5 -> 7404.39 | H8: USD/Horas | I8: =I6/I7 -> 1.6793427
B9: Costo + Gasto Fijo | C9: =C11+C12+C10 -> 536550 | E9: NET Margin | F9: =(I5-C13-F8-F5-C18*'Parámetros'!L8*I5)/I5 -> 0.3931
B10: Computador Herramientas Trabajo | C10: =6000000/30*F20*1.095 -> 536550
B11: - ROP Gasto | C11: =H20*AVERAGE('Parámetros'!G5:G6)*IF(C19=1,15%,1) -> 0
B12: - ROP Costo Fijo | C12: =H20*AVERAGE('Parámetros'!H5:H6)*IF(C19=1,15%,1) -> 0 | E12: Comisión Venta | F12: =I12*C17 -> 60077.259 | G12: Jugar con Net Margin | H12: PV COP | I12: =+(C13/(1-C17-F13-'Parámetros'!L5-'Parámetros'!L8*C18))+('Parámetros'!L9*C18) -> 600772.59
B13: T. C + G Equipo | C13: =C8+C9 -> 536550 | E13: NET Margin | F13: 0 | H13: PV USD | I13: =I12/'Parámetros'!L3 -> 169.23172
E14: Imp. Renta | F14: =(I12-F13-C12)*'Parámetros'!L6 -> 0 | H14: Horas | I14: 180
B15: Comisión Bruta | C15: 0.1 | E15: ICA | F15: =I12*'Parámetros'!L5 -> 4145.3309 | H15: USD/Horas | I15: =I13/I14 -> 0.9401762
B16: ¿Tipo de contrato vendedor? | C16: Prestación de Servicios
B17: Comisión Total | C17: =IF('PRICING PLANTILLA'!C16="Nómina",C15*1.38522,C15) -> 0.1
B18: ¿Pago con TC? | C18: 0 | F18: Proyectado
B19: ¿Staff Augmentation? | C19: 0
F20: =SUM(F22:F34) -> 2.45 | G20: =SUM(G22:G34) -> 0 | H20: =SUM(H22:H34) -> 0
B21: Equipo | C21: Salario Base | D21: Tipo Contrato | E21: Costo Total | F21: Dedicación | G21: Costo Final | H21: % Tiempo Equipo | I21: % Costo Equipo | J21: PV (USD)
B22: Software Developer Junior Nivel 1 | C22: =iferror(VLOOKUP(B22,'Parámetros'!A$1:B120,2, FALSE),"") | D22: Nómina | E22: =+iferror(IF(D22="Nómina",C22*1.38352,C22),"") -> 0 | F22: 1 | G22: =E22*F22 -> 0 | H22: =G22/(AVERAGE('Parámetros'!$F$5:$F$6)+$G$20) -> 0 | I22: =G22/$G$20 -> #DIV/0! | J22: =$I$13*I22 -> #DIV/0!
B23: Project Analyst Junior | C23: =iferror(VLOOKUP(B23,'Parámetros'!A$1:B121,2, FALSE),"") | D23: Nómina | E23: =+iferror(IF(D23="Nómina",C23*1.38352,C23),"") -> 0 | F23: 0.25 | G23: =E23*F23 -> 0 | H23: =G23/(AVERAGE('Parámetros'!$F$5:$F$6)+$G$20) -> 0 | I23: =G23/$G$20 -> #DIV/0! | J23: =$I$13*I23 -> #DIV/0!
B24: Diseñador Junior | C24: =iferror(VLOOKUP(B24,'Parámetros'!A$1:B122,2, FALSE),"") | D24: Nómina | E24: =+iferror(IF(D24="Nómina",C24*1.38352,C24),"") -> 0 | F24: 0.2 | G24: =E24*F24 -> 0 | H24: =G24/(AVERAGE('Parámetros'!$F$5:$F$6)+$G$20) -> 0 | I24: =G24/$G$20 -> #DIV/0! | J24: =$I$13*I24 -> #DIV/0!
C25: =iferror(VLOOKUP(B25,'Parámetros'!A$1:B123,2, FALSE),"") | D25: Nómina | E25: =+iferror(IF(D25="Nómina",C25*1.38352,C25),"") -> 0 | F25: 1 | G25: =E25*F25 -> 0 | H25: =G25/(AVERAGE('Parámetros'!$F$5:$F$6)+$G$20) -> 0 | I25: =G25/$G$20 -> #DIV/0! | J25: =$I$13*I25 -> #DIV/0!
C26: =iferror(VLOOKUP(B26,'Parámetros'!A$1:B124,2, FALSE),"") | E26: =+iferror(IF(D26="Nómina",C26*1.38352,C26),"") | G26: =E26*F26 -> 0 | H26: =G26/AVERAGE('Parámetros'!$F$5:$F$6) -> 0 | I26: =G26/$G$20 -> #DIV/0! | J26: =$I$13*I26 -> #DIV/0!
C27: =iferror(VLOOKUP(B27,'Parámetros'!A$1:B126,2, FALSE),"") | E27: =+iferror(IF(D27="Nómina",C27*1.38352,C27),"") | G27: =E27*F27 -> 0 | I27: =G27/$G$20 -> #DIV/0! | J27: =$I$13*I27 -> #DIV/0!
C28: =iferror(VLOOKUP(B28,'Parámetros'!A$1:B126,2, FALSE),"") | E28: =+iferror(IF(D28="Nómina",C28*1.38352,C28),"") | G28: =E28*F28 -> 0 | I28: =G28/$G$20 -> #DIV/0! | J28: =$I$13*I28 -> #DIV/0!
C29: =iferror(VLOOKUP(B29,'Parámetros'!A$1:B126,2, FALSE),"") | D29: Nómina | E29: =+iferror(IF(D29="Nómina",C29*1.38352,C29),"") -> 0 | G29: =E29*F29 -> 0 | I29: =G29/$G$20 -> #DIV/0! | J29: =$I$13*I29 -> #DIV/0!
C30: =iferror(VLOOKUP(B30,'Parámetros'!A$1:B126,2, FALSE),"") | E30: =+iferror(IF(D30="Nómina",C30*1.38352,C30),"") | G30: =E30*F30 -> 0 | I30: =G30/$G$20 -> #DIV/0! | J30: =$I$13*I30 -> #DIV/0!
C31: =iferror(VLOOKUP(B31,'Parámetros'!A$1:B126,2, FALSE),"") | E31: =+iferror(IF(D31="Nómina",C31*1.38352,C31),"") | G31: =E31*F31 -> 0 | I31: =G31/$G$20 -> #DIV/0! | J31: =$I$13*I31 -> #DIV/0!
C32: =iferror(VLOOKUP(B32,'Parámetros'!A$1:B126,2, FALSE),"") | E32: =+iferror(IF(D32="Nómina",C32*1.38352,C32),"") | G32: =E32*F32 -> 0 | I32: =G32/$G$20 -> #DIV/0! | J32: =$I$13*I32 -> #DIV/0!
C33: =iferror(VLOOKUP(B33,'Parámetros'!A$1:B126,2, FALSE),"") | E33: =+iferror(IF(D33="Nómina",C33*1.38352,C33),"") | G33: =E33*F33 -> 0 | I33: =G33/$G$20 -> #DIV/0! | J33: =$I$13*I33 -> #DIV/0!
C34: =iferror(VLOOKUP(B34,'Parámetros'!A$1:B126,2, FALSE),"") | D34: Nómina | E34: =+iferror(IF(D34="Nómina",C34*1.38352,C34),"") -> 0 | G34: =E34*F34 -> 0 | I34: =G34/$G$20 -> #DIV/0! | J34: =$I$13*I34 -> #DIV/0!
B36: COP | K36: USD
B37: Pricing | C37: Gross Margin | K37: Pricing | L37: Gross Margin
B39: Perfil | C39: Dedicación | D39: Capacidad Horas | E39: Precio COP | F39: Precio x Hora | K39: Perfil | L39: Dedicación | M39: Capacidad Horas | N39: Precio USD | O39: Precio x Hora
B40: =B22 -> Software Developer Junior Nivel 1 | C40: =F22 -> 1 | D40: =C40*180 -> 180 | E40: =IF(C$37="Gross Margin",I22*$I$5,IF(C$37="Net Margin",I22*$I$12,"Error")) -> #DIV/0! | F40: =iferror(E40/D40,0) -> 0 | K40: =B40 -> Software Developer Junior Nivel 1 | L40: =C40 -> 1 | M40: =D40 -> 180 | N40: =E40/'Parámetros'!$L$3 -> #DIV/0! | O40: =iferror(N40/M40,0) -> 0
B41: =B23 -> Project Analyst Junior | C41: =F23 -> 0.25 | D41: =C41*180 -> 45 | E41: =IF(C$37="Gross Margin",I23*$I$5,IF(C$37="Net Margin",I23*$I$12,"Error")) -> #DIV/0! | F41: =iferror(E41/D41,0) -> 0 | K41: =B41 -> Project Analyst Junior | L41: =C41 -> 0.25 | M41: =D41 -> 45 | N41: =E41/'Parámetros'!$L$3 -> #DIV/0! | O41: =iferror(N41/M41,0) -> 0
B42: =B24 -> Diseñador Junior | C42: =F24 -> 0.2 | D42: =C42*180 -> 36 | E42: =IF(C$37="Gross Margin",I24*$I$5,IF(C$37="Net Margin",I24*$I$12,"Error")) -> #DIV/0! | F42: =iferror(E42/D42,0) -> 0 | K42: =B42 -> Diseñador Junior | L42: =C42 -> 0.2 | M42: =D42 -> 36 | N42: =E42/'Parámetros'!$L$3 -> #DIV/0! | O42: =iferror(N42/M42,0) -> 0
B43: =B25 | C43: =F25 -> 1 | D43: =C43*180 -> 180 | E43: =IF(C$37="Gross Margin",I25*$I$5,IF(C$37="Net Margin",I25*$I$12,"Error")) -> #DIV/0! | F43: =iferror(E43/D43,0) -> 0 | K43: =B43 | L43: =C43 -> 1 | M43: =D43 -> 180 | N43: =E43/'Parámetros'!$L$3 -> #DIV/0! | O43: =iferror(N43/M43,0) -> 0
...

Sheet Parámetros
A1: Perfil | B1: Salario | C1: Costo Empresa
A2: Forward Deployed Product manager | B2: 5000000 | C2: =B2*1.38 -> 6900000 | K2: Parámetros
A3: DevOps Engineer Senior | B3: 8000000 | C3: =B3*1.38 -> 11040000 | K3: TRM | L3: 3550 | O3: =IFERROR(__xludf.DUMMYFUNCTION("GOOGLEFINANCE(""currency:USDCOP"",""price"",(TODAY()-20)-20,60)"),"Date") -> Date | P3: =IFERROR(__xludf.DUMMYFUNCTION("""COMPUTED_VALUE"""),"Close") -> Close
A4: Forward Deployed Enginnier | B4: 7000000 | C4: =B4*1.38 -> 9660000 | F4: Bolsa | G4: Gastos Fijos | H4: Costos | K4: # Proyectos x Pod | L4: 1 | O4: =IFERROR(__xludf.DUMMYFUNCTION("""COMPUTED_VALUE"""),46061.99861111111) -> 46061.999 | P4: =IFERROR(__xludf.DUMMYFUNCTION("""COMPUTED_VALUE"""),3657.237) -> 3657.237
A5: Forward Deployed Pruduct experience | B5: 5000000 | C5: =B5*1.38 -> 6900000 | E5: Diciembre | F5: 322239393 | G5: 219207359 | H5: =21584031+12296884 -> 33880915 | K5: ICA | L5: =6.9/1000 -> 0.0069 | O5: =IFERROR(__xludf.DUMMYFUNCTION("""COMPUTED_VALUE"""),46062.99861111111) -> 46062.999 | P5: =IFERROR(__xludf.DUMMYFUNCTION("""COMPUTED_VALUE"""),3668.26) -> 3668.26
A6: Tech Leald Orchestaror | B6: 10000000 | C6: =B6*1.38 -> 13800000 | E6: Enero | F6: 345674120 | G6: =153922294-23803671 -> 130118623 | H6: =18000124+17676944 -> 35677068 | K6: Renta | L6: 0 | O6: =IFERROR(__xludf.DUMMYFUNCTION("""COMPUTED_VALUE"""),46063.99861111111) -> 46063.999 | P6: =IFERROR(__xludf.DUMMYFUNCTION("""COMPUTED_VALUE"""),3663.72) -> 3663.72 | V6: 2022-Apr | W6: 4055.2343
A7: QA Engineer Semi Senior | B7: 3000000 | C7: =B7*1.38 -> 4140000 | E7: Febrero | F7: 339294343 | G7: =163844091-30578849 -> 133265242 | H7: =17853308+7452783 -> 25306091 | K7: Face Value Comisión | L7: 0.1 | O7: =IFERROR(__xludf.DUMMYFUNCTION("""COMPUTED_VALUE"""),46064.99861111111) -> 46064.999 | P7: =IFERROR(__xludf.DUMMYFUNCTION("""COMPUTED_VALUE"""),3669.53) -> 3669.53 | V7: 2022-May | W7: 4377.3221
A8: Software Developer Semi Senior Nivel 1 | B8: 5000000 | C8: =B8*1.38 -> 6900000 | E8: Marzo | F8: 333648543 | G8: =154935476-9678137 -> 145257339 | H8: =7027325+20727068 -> 27754393 | K8: Comisión TC | L8: 0.029 | O8: =IFERROR(__xludf.DUMMYFUNCTION("""COMPUTED_VALUE"""),46065.99861111111) -> 46065.999 | P8: =IFERROR(__xludf.DUMMYFUNCTION("""COMPUTED_VALUE"""),3668.0) -> 3668 | W8: #DIV/0!
A9: Software Developer Semi Senior Nivel 2 | B9: 7000000 | C9: =B9*1.38 -> 9660000 | E9: Abril | F9: 324919373 | G9: =179893216-43368730 -> 136524486 | H9: =16643013-1443598+7452783 -> 22652198 | K9: Comisión 2 | L9: 0.3 | O9: =IFERROR(__xludf.DUMMYFUNCTION("""COMPUTED_VALUE"""),46066.99861111111) -> 46066.999 | P9: =IFERROR(__xludf.DUMMYFUNCTION("""COMPUTED_VALUE"""),3664.65) -> 3664.65 | V9: Grand Total | W9: 4242.253
A10: Software Developer Senior Nivel 1 | B10: 9000000 | C10: =B10*1.38 -> 12420000 | E10: Mayo | F10: 354200345 | G10: =175297648-34194521 -> 141103127 | H10: =23598164-1138139+7452783 -> 29912808 | O10: =IFERROR(__xludf.DUMMYFUNCTION("""COMPUTED_VALUE"""),46067.99861111111) -> 46067.999 | P10: =IFERROR(__xludf.DUMMYFUNCTION("""COMPUTED_VALUE"""),3618.33) -> 3618.33
A11: Software Developer Senior Nivel 2 | B11: 12000000 | C11: =B11*1.38 -> 16560000 | O11: =IFERROR(__xludf.DUMMYFUNCTION("""COMPUTED_VALUE"""),46069.99861111111) -> 46069.999 | P11: =IFERROR(__xludf.DUMMYFUNCTION("""COMPUTED_VALUE"""),3656.07) -> 3656.07
A12: Forward Deployed Enginnier - On Site | B12: 9000000 | C12: =B12*1.38 -> 12420000 | O12: =IFERROR(__xludf.DUMMYFUNCTION("""COMPUTED_VALUE"""),46070.99861111111) -> 46070.999 | P12: =IFERROR(__xludf.DUMMYFUNCTION("""COMPUTED_VALUE"""),3663.75) -> 3663.75
O13: =IFERROR(__xludf.DUMMYFUNCTION("""COMPUTED_VALUE"""),46071.99861111111) -> 46071.999 | P13: =IFERROR(__xludf.DUMMYFUNCTION("""COMPUTED_VALUE"""),3678.28) -> 3678.28
O14: =IFERROR(__xludf.DUMMYFUNCTION("""COMPUTED_VALUE"""),46072.99861111111) -> 46072.999 | P14: =IFERROR(__xludf.DUMMYFUNCTION("""COMPUTED_VALUE"""),3698.79) -> 3698.79
O15: =IFERROR(__xludf.DUMMYFUNCTION("""COMPUTED_VALUE"""),46073.99861111111) -> 46073.999 | P15: =IFERROR(__xludf.DUMMYFUNCTION("""COMPUTED_VALUE"""),3706.17) -> 3706.17
O16: =IFERROR(__xludf.DUMMYFUNCTION("""COMPUTED_VALUE"""),46074.99861111111) -> 46074.999 | P16: =IFERROR(__xludf.DUMMYFUNCTION("""COMPUTED_VALUE"""),3647.348) -> 3647.348
O17: =IFERROR(__xludf.DUMMYFUNCTION("""COMPUTED_VALUE"""),46075.99861111111) -> 46075.999 | P17: =IFERROR(__xludf.DUMMYFUNCTION("""COMPUTED_VALUE"""),3647.348) -> 3647.348
O18: =IFERROR(__xludf.DUMMYFUNCTION("""COMPUTED_VALUE"""),46076.99861111111) -> 46076.999 | P18: =IFERROR(__xludf.DUMMYFUNCTION("""COMPUTED_VALUE"""),3691.94) -> 3691.94
O19: =IFERROR(__xludf.DUMMYFUNCTION("""COMPUTED_VALUE"""),46077.99861111111) -> 46077.999 | P19: =IFERROR(__xludf.DUMMYFUNCTION("""COMPUTED_VALUE"""),3710.11) -> 3710.11
O20: =IFERROR(__xludf.DUMMYFUNCTION("""COMPUTED_VALUE"""),46078.99861111111) -> 46078.999 | P20: =IFERROR(__xludf.DUMMYFUNCTION("""COMPUTED_VALUE"""),3697.69) -> 3697.69
O21: =IFERROR(__xludf.DUMMYFUNCTION("""COMPUTED_VALUE"""),46079.99861111111) -> 46079.999 | P21: =IFERROR(__xludf.DUMMYFUNCTION("""COMPUTED_VALUE"""),3764.29) -> 3764.29
O22: =IFERROR(__xludf.DUMMYFUNCTION("""COMPUTED_VALUE"""),46080.99861111111) -> 46080.999 | P22: =IFERROR(__xludf.DUMMYFUNCTION("""COMPUTED_VALUE"""),3759.93) -> 3759.93
O23: =IFERROR(__xludf.DUMMYFUNCTION("""COMPUTED_VALUE"""),46081.99861111111) -> 46081.999 | P23: =IFERROR(__xludf.DUMMYFUNCTION("""COMPUTED_VALUE"""),3716.57) -> 3716.57
O24: =IFERROR(__xludf.DUMMYFUNCTION("""COMPUTED_VALUE"""),46082.99861111111) -> 46082.999 | P24: =IFERROR(__xludf.DUMMYFUNCTION("""COMPUTED_VALUE"""),3716.57) -> 3716.57
O25: =IFERROR(__xludf.DUMMYFUNCTION("""COMPUTED_VALUE"""),46083.99861111111) -> 46083.999 | P25: =IFERROR(__xludf.DUMMYFUNCTION("""COMPUTED_VALUE"""),3770.8) -> 3770.8
O26: =IFERROR(__xludf.DUMMYFUNCTION("""COMPUTED_VALUE"""),46084.99861111111) -> 46084.999 | P26: =IFERROR(__xludf.DUMMYFUNCTION("""COMPUTED_VALUE"""),3801.26) -> 3801.26
O27: =IFERROR(__xludf.DUMMYFUNCTION("""COMPUTED_VALUE"""),46085.99861111111) -> 46085.999 | P27: =IFERROR(__xludf.DUMMYFUNCTION("""COMPUTED_VALUE"""),3759.11) -> 3759.11
O28: =IFERROR(__xludf.DUMMYFUNCTION("""COMPUTED_VALUE"""),46086.99861111111) -> 46086.999 | P28: =IFERROR(__xludf.DUMMYFUNCTION("""COMPUTED_VALUE"""),3788.48) -> 3788.48
O29: =IFERROR(__xludf.DUMMYFUNCTION("""COMPUTED_VALUE"""),46087.99861111111) -> 46087.999 | P29: =IFERROR(__xludf.DUMMYFUNCTION("""COMPUTED_VALUE"""),3782.66) -> 3782.66
O30: =IFERROR(__xludf.DUMMYFUNCTION("""COMPUTED_VALUE"""),46088.99861111111) -> 46088.999 | P30: =IFERROR(__xludf.DUMMYFUNCTION("""COMPUTED_VALUE"""),3711.902) -> 3711.902
O31: =IFERROR(__xludf.DUMMYFUNCTION("""COMPUTED_VALUE"""),46090.99861111111) -> 46090.999 | P31: =IFERROR(__xludf.DUMMYFUNCTION("""COMPUTED_VALUE"""),3761.83) -> 3761.83
O32: =IFERROR(__xludf.DUMMYFUNCTION("""COMPUTED_VALUE"""),46091.99861111111) -> 46091.999 | P32: =IFERROR(__xludf.DUMMYFUNCTION("""COMPUTED_VALUE"""),3709.07) -> 3709.07
O33: =IFERROR(__xludf.DUMMYFUNCTION("""COMPUTED_VALUE"""),46092.99861111111) -> 46092.999 | P33: =IFERROR(__xludf.DUMMYFUNCTION("""COMPUTED_VALUE"""),3703.43) -> 3703.43
O34: =IFERROR(__xludf.DUMMYFUNCTION("""COMPUTED_VALUE"""),46093.99861111111) -> 46093.999 | P34: =IFERROR(__xludf.DUMMYFUNCTION("""COMPUTED_VALUE"""),3692.56) -> 3692.56
O35: =IFERROR(__xludf.DUMMYFUNCTION("""COMPUTED_VALUE"""),46094.99861111111) -> 46094.999 | P35: =IFERROR(__xludf.DUMMYFUNCTION("""COMPUTED_VALUE"""),3704.68) -> 3704.68
O36: =IFERROR(__xludf.DUMMYFUNCTION("""COMPUTED_VALUE"""),46095.99861111111) -> 46095.999 | P36: =IFERROR(__xludf.DUMMYFUNCTION("""COMPUTED_VALUE"""),3638.607) -> 3638.607
O37: =IFERROR(__xludf.DUMMYFUNCTION("""COMPUTED_VALUE"""),46097.99861111111) -> 46097.999 | P37: =IFERROR(__xludf.DUMMYFUNCTION("""COMPUTED_VALUE"""),3702.24) -> 3702.24
O38: =IFERROR(__xludf.DUMMYFUNCTION("""COMPUTED_VALUE"""),46098.99861111111) -> 46098.999 | P38: =IFERROR(__xludf.DUMMYFUNCTION("""COMPUTED_VALUE"""),3689.13572) -> 3689.1357
O39: =IFERROR(__xludf.DUMMYFUNCTION("""COMPUTED_VALUE"""),46099.99861111111) -> 46099.999 | P39: =IFERROR(__xludf.DUMMYFUNCTION("""COMPUTED_VALUE"""),3706.06) -> 3706.06
O40: =IFERROR(__xludf.DUMMYFUNCTION("""COMPUTED_VALUE"""),46100.99861111111) -> 46100.999 | P40: =IFERROR(__xludf.DUMMYFUNCTION("""COMPUTED_VALUE"""),3704.24) -> 3704.24
...

Sheet Política de Servidores
B4: - Si el despliegue es en servidor Imagine: Despliegue sin costo pero mensualidad entre 25 - 50 usd* x plataforma (App o Web)-
B5: *Precio promedio, sujeto al consumo real, en caso de tener un consumo mayor se realizará el cobro real, adicional al servicio de administración que corresponde al 25% del consumo.
B6: Precio por instancia, ej: si tienen instancia de pruebas es $25 + producción $25. Y la de pruebas no la debemos cobrar si están pagando equipo dedicado
B7: - Si se despliega en un servidor del cliente: En el pricing debe contemplarse un 12.5% de devops.
B8: - Si inicialmente se despliega en un servidor de Imagine y se migra al del cliente: requerimos 3 días hábiles y tendrá un costo aproximado de 1.500 USD (se confirma con cotización específica del despliegue)
B9: - Sujeto a configuraciones y parámetros a configurar en el servidor externo
B10: - Si migra de un servidor externo a Imagine, el tiempo será de 3 días hábiles y tendrá un costo aproximado de 1.500 USD (se confirma con cotización específica del despliegue)
B11: - Sujeto a configuraciones y parámetros a configurar en el servidor externo

Sheet Política Comisiones
B2: Esquema de comisiones:
B4: Comisiones | D4: Referido | E4: KAM | F4: Comisiones
B5: Fuente lead | C5: Mercadeo | D5: 0.02 | E5: 0.1 | F5: =D5+E5 -> 0.12
C6: Directo | D6: 0 | E6: 0.1 | F6: =D6+E6 -> 0.1
C7: Referido Imagine | D7: 0.05 | E7: 0.05 | F7: =D7+E7 -> 0.1
C8: Network- Cold Calling | D8: 0.02 | E8: 0.065 | F8: =D8+E8 -> 0.085
C9: Cold Calling / Mailing | D9: 0.02 | E9: 0.065 | F9: =D9+E9 -> 0.085
B11: Definiciones
B12: Mercadeo | C12: Lisseth Carhuapoma
B13: Directo | C13: Venta directa del comercial
B14: Referido Imagine | C14: Personal de Imagine que ayuda a la obtención de una venta.
B15: Network - Cold Calling | C15: Personal comercial que ayuda a la obtención de una venta.
B16: Cold Calling / Mailing | C16: Personal comercial que ayuda a la obtención de una venta.
B19: Esquema de bonos de reclutamiento:
B21: Seniority | C21: Bono
B22: Perfil Semi Sr. | C22: 350000
B23: Perfil Sr. | C23: 600000
B24: Perdil Junior | C24: 200000

Sheet Foward Deployed Enginnier
B2: Línea de Negocio | C2: Equipo Dedicado
B3: ¿Tipo de contrato vendedor? | C3: Deel/Ontop
B4: Comisión vendedor | C4: 0.05
B5: ¿Cuál es la fuente de tu lead? | C5: Directo
B6: Perfil Network | C6: Perfil Sr.
B7: ¿Pago con TC? | C7: 0 | F7: Gross Margin Meta | G7: =VLOOKUP($C$2,'Parámetros'!$A$118:$D$124,3,0) -> 0.4
B8: Factoring | C8: 0 | F8: =IF(D13>=G7,"Dentro del margen","¡Por debajo del margen!") -> ¡Por debajo del margen!
B9: Tecnologia
B10: Tiempo Duración: Mes | C10: 4
F11: COP | G11: USD
B12: Jugar con Gross Margin | C12: Comisión Venta | D12: =F12*C4+IFS(C5="Cold Calling",2%*138.3522%,C5="Mercadeo",2%*101%,C5="Network - Cold Calling",2%*138.3522%,C5="Referido Imagine",5%*138.3522%,C5="Directo",0)*F12+ifs(AND(C6="Perfil Jr.",C2="Network"),200000,AND(C6="Perfil Sr.",C2="Network"),350000,AND(C2="Network",C6="Perfil Semi Senior"), 600000,C2="Proyecto",1,C2="Equipo dedicado",1,C2="Servidores",1,C2="Enterprise",1,C2="Descubrimiento",1) -> 2903226.8 | E12: Precio Total | F12: =((C61+C57+C59)/((1-D13-'Parámetros'!L8*C7)))*IF(C8=1,102.4%,1) -> 58064516 | G12: =F12/'Parámetros'!$L$3 -> 16356.202 | I12: 160 | J12: 1
C13: Gross Margin | D13: 0.38 | E13: Precio mensual | F13: =F12/C10 -> 14516129 | G13: =F13/'Parámetros'!$L$3 -> 4089.0504 | I13: 12 | J13: =I13*J12/I12 -> 0.075
C14: ICA | D14: =F12*'Parámetros'!L5 -> 400645.16 | E14: Precio/Horas | F14: =F12/SUM(D43:D52)/C10 -> 80645.161 | G14: =G12/SUM(D43:D52)/C10 -> 22.716947
C15: NET Margin | D15: =(F12-C62-D14-D12-C7*'Parámetros'!L8*F12-IF(C8=1,2.4%,0)*F12)/F12 -> 0.25942405 | I15: 12 horas | J15: 3127889.9
I16: 20 horas | J16: 5044796.6
B18: Jugar con Net Margin | C18: Comisión Venta | D18: =F18*C4+IFS(C5="Cold Calling",2%*138.3522%,C5="Mercadeo",2%*101%,C5="Network - Cold Calling",2%*138.3522%,C5="Referido Imagine",5%*138.3522%,C5="Directo",0)*F18 -> 2671061.2 | E18: Precio Total | F18: =+C62/((1-IFS(C5="Cold Calling",2%*138.3522%,C5="Mercadeo",2%*101%,C5="Network - Cold Calling",2%*138.3522%,C5="Referido Imagine",5%*138.3522%,C5="Directo",0)-C4-D19-'Parámetros'!L5-C7*'Parámetros'!L8))*IF(C8=1,102.4%,1) -> 53421225 | G18: =F18/'Parámetros'!L3 -> 15048.232
C19: NET Margin | D19: 0.2 | E19: Precio mensual | F19: =F18/C10 -> 13355306 | G19: =G18/C10 -> 3762.0581
C20: ICA | D20: =F18*'Parámetros'!L5 -> 368606.45 | E20: Precio/Horas | F20: =F18/SUM(D43:D52)/C10 -> 74196.146 | G20: =G18/SUM(D43:D52)/C10 -> 20.900323
C21: Gross Margin | D21: =(((F18-C57-C59-C61-C7*'Parámetros'!L8*F18)-IF(C8=1,2.4%,0)*F18)/F18) -> 0.32611055
B23: ='Parámetros'!B149 -> Considerar como mínimo por cada Dev: PM:33%, QA:20%, Diseño:10%
E25: =SUM(E27:E34) -> 1
B26: Equipo | C26: Salario Base | D26: Tipo Contrato | E26: Dedicación | F26: Costo mensual | G26: Costo total | H26: % Tiempo Equipo
A27: =IFERROR(__xludf.DUMMYFUNCTION("COUNTIF(SPLIT(B27,"" ""),""Developer"")"),0.0) -> 0 | B27: Forward Deployed Enginnier - On Site | C27: =IFERROR(VLOOKUP(B27,'Parámetros'!A$1:B113,2, FALSE),"") -> 9000000 | D27: P. Servicios | E27: 1 | F27: =+IFERROR(IF(D27="Nómina",C27*1.38352,C27),"")*E27 -> 9000000 | G27: =F27*C$10 -> 36000000 | H27: =F27/(AVERAGE('Parámetros'!$F$5:$F$6)+$F$37) -> 0.026242376
A28: =IFERROR(__xludf.DUMMYFUNCTION("COUNTIF(SPLIT(B28,"" ""),""Developer"")"),0.0) -> 0
A29: =IFERROR(__xludf.DUMMYFUNCTION("COUNTIF(SPLIT(B29,"" ""),""Developer"")"),0.0) -> 0
A30: =IFERROR(__xludf.DUMMYFUNCTION("COUNTIF(SPLIT(B30,"" ""),""Developer"")"),0.0) -> 0 | C30: =IFERROR(VLOOKUP(B30,'Parámetros'!A$1:B116,2, FALSE),"") | F30: =+IFERROR(IF(D30="Nómina",C30*1.38352,C30),"")*E30*105% -> 0 | G30: =F30*C$10 -> 0 | H30: =G30/(AVERAGE('Parámetros'!$F$5:$F$6)+$F$37) -> 0
A31: =IFERROR(__xludf.DUMMYFUNCTION("COUNTIF(SPLIT(B31,"" ""),""Developer"")"),0.0) -> 0
A32: =IFERROR(__xludf.DUMMYFUNCTION("COUNTIF(SPLIT(B32,"" ""),""Developer"")"),0.0) -> 0 | F32: =+IFERROR(IF(D32="Nómina",C32*1.38352,C32),"")*E32*105% -> 0 | G32: =F32*C$10 -> 0 | H32: =G32/(AVERAGE('Parámetros'!$F$5:$F$6)+$F$37) -> 0
A33: =IFERROR(__xludf.DUMMYFUNCTION("COUNTIF(SPLIT(B33,"" ""),""Developer"")"),0.0) -> 0 | F33: =+IFERROR(IF(D33="Nómina",C33*1.38352,C33),"")*E33*105% -> 0 | G33: =F33*C$10 -> 0 | H33: =G33/(AVERAGE('Parámetros'!$F$5:$F$6)+$F$37) -> 0
A34: =IFERROR(__xludf.DUMMYFUNCTION("COUNTIF(SPLIT(B34,"" ""),""Developer"")"),0.0) -> 0 | C34: =IFERROR(VLOOKUP(B34,'Parámetros'!A$1:B120,2, FALSE),"") | F34: =+IFERROR(IF(D34="Nómina",C34*1.38352,C34),"")*E34*105% -> 0 | G34: =F34*C$10 -> 0 | H34: =G34/(AVERAGE('Parámetros'!$F$5:$F$6)+$F$37) -> 0
C35: =IFERROR(VLOOKUP(B35,'Parámetros'!A$1:B121,2, FALSE),"") | F35: =+IFERROR(IF(D35="Nómina",C35*1.38352,C35),"")*E35*105% -> 0 | G35: =F35*C$10 -> 0 | H35: =G35/(AVERAGE('Parámetros'!$F$5:$F$6)+$F$37) -> 0
C36: =IFERROR(VLOOKUP(B36,'Parámetros'!A$1:B122,2, FALSE),"") | F36: =+IFERROR(IF(D36="Nómina",C36*1.38352,C36),"")*E36*105% -> 0 | G36: =F36*C$10 -> 0 | H36: =G36/(AVERAGE('Parámetros'!$F$5:$F$6)+$F$37) -> 0
F37: =SUM(F27:F36) -> 9000000 | G37: =SUM(G27:G36) -> 36000000 | H37: =SUM(H27:H36) -> 0.026242376
C40: Gross Margin | D40: USD
B42: Equipo | C42: Dedicación | D42: Capacidad Horas | E42: Precio x Hora | F42: Precio Total
B43: =B27 -> Forward Deployed Enginnier - On Site | C43: =E27 -> 1 | D43: =C43*180 -> 180 | E43: =IFERROR((IF($C$40="Gross Margin",F27/$F$37*$F$12,IF($C$40="Net Margin",F27/$F$37*$F$18,"Error")))/D43,"")/IF($D$40="USD",'Parámetros'!$L$3,1)/$C$10 -> 22.716947 | F43: =E43*D43 -> 4089.0504
B44: =B28 | C44: =E28 | D44: =C44*180 -> 0 | E44: =IFERROR((IF($C$40="Gross Margin",F28/$F$37*$F$12,IF($C$40="Net Margin",F28/$F$37*$F$18,"Error")))/D44,"")/IF($D$40="USD",'Parámetros'!$L$3,1)/$C$10 -> 0 | F44: =E44*D44 -> 0
B45: =B29 | C45: =E29 | D45: =C45*180 -> 0 | E45: =IFERROR((IF($C$40="Gross Margin",F29/$F$37*$F$12,IF($C$40="Net Margin",F29/$F$37*$F$18,"Error")))/D45,"")/IF($D$40="USD",'Parámetros'!$L$3,1)/$C$10 -> 0 | F45: =E45*D45 -> 0
B46: =B30 | C46: =E30 | D46: =C46*180 -> 0 | E46: =IFERROR((IF($C$40="Gross Margin",F30/$F$37*$F$12,IF($C$40="Net Margin",F30/$F$37*$F$18,"Error")))/D46,"")/IF($D$40="USD",'Parámetros'!$L$3,1)/$C$10 -> 0 | F46: =E46*D46 -> 0
B47: =B31 | C47: =E31 | D47: =C47*180 -> 0 | E47: =IFERROR((IF($C$40="Gross Margin",F31/$F$37*$F$12,IF($C$40="Net Margin",F31/$F$37*$F$18,"Error")))/D47,"")/IF($D$40="USD",'Parámetros'!$L$3,1)/$C$10 -> 0 | F47: =E47*D47 -> 0
...

Sheet Equipo Base
B2: Línea de Negocio | C2: Equipo Dedicado
B3: ¿Tipo de contrato vendedor? | C3: Deel/Ontop
B4: Comisión vendedor | C4: 0.08
B5: ¿Cuál es la fuente de tu lead? | C5: Directo
B6: Perfil Network | C6: Perfil Sr.
B7: ¿Pago con TC? | C7: 0 | F7: Gross Margin Meta | G7: =VLOOKUP($C$2,'Parámetros'!$A$118:$D$124,3,0) -> 0.4
B8: Factoring | C8: 0 | F8: =IF(D13>=G7,"Dentro del margen","¡Por debajo del margen!") -> Dentro del margen
B9: Tecnologia
B10: Tiempo Duración: Mes | C10: 0.25
F11: COP | G11: USD
B12: Jugar con Gross Margin | C12: Comisión Venta | D12: =F12*C4+IFS(C5="Cold Calling",2%*138.3522%,C5="Mercadeo",2%*101%,C5="Network - Cold Calling",2%*138.3522%,C5="Referido Imagine",5%*138.3522%,C5="Directo",0)*F12+ifs(AND(C6="Perfil Jr.",C2="Network"),200000,AND(C6="Perfil Sr.",C2="Network"),350000,AND(C2="Network",C6="Perfil Semi Senior"), 600000,C2="Proyecto",1,C2="Equipo dedicado",1,C2="Servidores",1,C2="Enterprise",1,C2="Descubrimiento",1) -> 460001 | E12: Precio Total | F12: =((C61+C57+C59)/((1-D13-'Parámetros'!L8*C7)))*IF(C8=1,102.4%,1) -> 5750000 | G12: =F12/'Parámetros'!$L$3 -> 1619.7183 | I12: 160 | J12: 1
C13: Gross Margin | D13: 0.75 | E13: Precio mensual | F13: =F12/C10 -> 23000000 | G13: =F13/'Parámetros'!$L$3 -> 6478.8732 | I13: 12 | J13: =I13*J12/I12 -> 0.075
C14: ICA | D14: =F12*'Parámetros'!L5 -> 39675 | E14: Precio/Horas | F14: =F12/SUM(D43:D52)/C10 -> 111111.11 | G14: =G12/SUM(D43:D52)/C10 -> 31.298905
C15: NET Margin | D15: =(F12-C62-D14-D12-C7*'Parámetros'!L8*F12-IF(C8=1,2.4%,0)*F12)/F12 -> 0.28892974 | I15: 12 horas | J15: 3127889.9
I16: 20 horas | J16: 5044796.6
B18: Jugar con Net Margin | C18: Comisión Venta | D18: =F18*C4+IFS(C5="Cold Calling",2%*138.3522%,C5="Mercadeo",2%*101%,C5="Network - Cold Calling",2%*138.3522%,C5="Referido Imagine",5%*138.3522%,C5="Directo",0)*F18 -> 402633.91 | E18: Precio Total | F18: =+C62/((1-IFS(C5="Cold Calling",2%*138.3522%,C5="Mercadeo",2%*101%,C5="Network - Cold Calling",2%*138.3522%,C5="Referido Imagine",5%*138.3522%,C5="Directo",0)-C4-D19-'Parámetros'!L5-C7*'Parámetros'!L8))*IF(C8=1,102.4%,1) -> 5032923.8 | G18: =F18/'Parámetros'!L3 -> 1417.725
C19: NET Margin | D19: 0.2 | E19: Precio mensual | F19: =F18/C10 -> 20131695 | G19: =G18/C10 -> 5670.9001
C20: ICA | D20: =F18*'Parámetros'!L5 -> 34727.174 | E20: Precio/Horas | F20: =F18/SUM(D43:D52)/C10 -> 97254.567 | G20: =G18/SUM(D43:D52)/C10 -> 27.395653
C21: Gross Margin | D21: =(((F18-C57-C59-C61-C7*'Parámetros'!L8*F18)-IF(C8=1,2.4%,0)*F18)/F18) -> 0.71438074
B23: ='Parámetros'!B149 -> Considerar como mínimo por cada Dev: PM:33%, QA:20%, Diseño:10%
E25: =SUM(E27:E34) -> 1.15
B26: Equipo | C26: Salario Base | D26: Tipo Contrato | E26: Dedicación | F26: Costo mensual | G26: Costo total | H26: % Tiempo Equipo
A27: =IFERROR(__xludf.DUMMYFUNCTION("COUNTIF(SPLIT(B27,"" ""),""Developer"")"),0.0) -> 0 | B27: Forward Deployed Product manager | C27: =IFERROR(VLOOKUP(B27,'Parámetros'!A$1:B113,2, FALSE),"") -> 5000000 | D27: P. Servicios | E27: 1 | F27: =+IFERROR(IF(D27="Nómina",C27*1.38352,C27),"")*E27 -> 5000000 | G27: =F27*C$10 -> 1250000 | H27: =F27/(AVERAGE('Parámetros'!$F$5:$F$6)+$F$37) -> 0.014718577
A28: =IFERROR(__xludf.DUMMYFUNCTION("COUNTIF(SPLIT(B28,"" ""),""Developer"")"),0.0) -> 0 | B28: Forward Deployed Enginnier | C28: 9000000 | D28: P. Servicios | F28: =+IFERROR(IF(D28="Nómina",C28*1.38352,C28),"")*E28 -> 0 | G28: =F28*C$10 -> 0 | H28: =G28/(AVERAGE('Parámetros'!$F$5:$F$6)+$F$37) -> 0
A29: =IFERROR(__xludf.DUMMYFUNCTION("COUNTIF(SPLIT(B29,"" ""),""Developer"")"),0.0) -> 0 | B29: Forward Deployed Pruduct experience | C29: =IFERROR(VLOOKUP(B29,'Parámetros'!A$1:B115,2, FALSE),"") -> 5000000 | D29: P. Servicios | E29: 0.15 | F29: =+IFERROR(IF(D29="Nómina",C29*1.38352,C29),"")*E29 -> 750000 | G29: =F29*C$10 -> 187500 | H29: =G29/(AVERAGE('Parámetros'!$F$5:$F$6)+$F$37) -> 0.00055194663
A30: =IFERROR(__xludf.DUMMYFUNCTION("COUNTIF(SPLIT(B30,"" ""),""Developer"")"),0.0) -> 0 | B30: Forward Deployed Enginnier | C30: 9000000 | D30: P. Servicios | F30: =+IFERROR(IF(D30="Nómina",C30*1.38352,C30),"")*E30 -> 0 | G30: =F30*C$10 -> 0 | H30: =G30/(AVERAGE('Parámetros'!$F$5:$F$6)+$F$37) -> 0
A31: =IFERROR(__xludf.DUMMYFUNCTION("COUNTIF(SPLIT(B31,"" ""),""Developer"")"),0.0) -> 0
A32: =IFERROR(__xludf.DUMMYFUNCTION("COUNTIF(SPLIT(B32,"" ""),""Developer"")"),0.0) -> 0 | F32: =+IFERROR(IF(D32="Nómina",C32*1.38352,C32),"")*E32*105% -> 0 | G32: =F32*C$10 -> 0 | H32: =G32/(AVERAGE('Parámetros'!$F$5:$F$6)+$F$37) -> 0
A33: =IFERROR(__xludf.DUMMYFUNCTION("COUNTIF(SPLIT(B33,"" ""),""Developer"")"),0.0) -> 0 | F33: =+IFERROR(IF(D33="Nómina",C33*1.38352,C33),"")*E33*105% -> 0 | G33: =F33*C$10 -> 0 | H33: =G33/(AVERAGE('Parámetros'!$F$5:$F$6)+$F$37) -> 0
A34: =IFERROR(__xludf.DUMMYFUNCTION("COUNTIF(SPLIT(B34,"" ""),""Developer"")"),0.0) -> 0 | C34: =IFERROR(VLOOKUP(B34,'Parámetros'!A$1:B120,2, FALSE),"") | F34: =+IFERROR(IF(D34="Nómina",C34*1.38352,C34),"")*E34*105% -> 0 | G34: =F34*C$10 -> 0 | H34: =G34/(AVERAGE('Parámetros'!$F$5:$F$6)+$F$37) -> 0
C35: =IFERROR(VLOOKUP(B35,'Parámetros'!A$1:B121,2, FALSE),"") | F35: =+IFERROR(IF(D35="Nómina",C35*1.38352,C35),"")*E35*105% -> 0 | G35: =F35*C$10 -> 0 | H35: =G35/(AVERAGE('Parámetros'!$F$5:$F$6)+$F$37) -> 0
C36: =IFERROR(VLOOKUP(B36,'Parámetros'!A$1:B122,2, FALSE),"") | F36: =+IFERROR(IF(D36="Nómina",C36*1.38352,C36),"")*E36*105% -> 0 | G36: =F36*C$10 -> 0 | H36: =G36/(AVERAGE('Parámetros'!$F$5:$F$6)+$F$37) -> 0
F37: =SUM(F27:F36) -> 5750000 | G37: =SUM(G27:G36) -> 1437500 | H37: =SUM(H27:H36) -> 0.015270523
C40: Gross Margin | D40: USD
B42: Equipo | C42: Dedicación | D42: Capacidad Horas | E42: Precio x Hora | F42: Precio Total
B43: =B27 -> Forward Deployed Product manager | C43: =E27 -> 1 | D43: =C43*180 -> 180 | E43: =IFERROR((IF($C$40="Gross Margin",F27/$F$37*$F$12,IF($C$40="Net Margin",F27/$F$37*$F$18,"Error")))/D43,"")/IF($D$40="USD",'Parámetros'!$L$3,1)/$C$10 -> 31.298905 | F43: =E43*D43 -> 5633.8028
B44: =B28 -> Forward Deployed Enginnier | C44: =E28 | D44: =C44*180 -> 0 | E44: =IFERROR((IF($C$40="Gross Margin",F28/$F$37*$F$12,IF($C$40="Net Margin",F28/$F$37*$F$18,"Error")))/D44,"")/IF($D$40="USD",'Parámetros'!$L$3,1)/$C$10 -> 0 | F44: =E44*D44 -> 0
B45: =B29 -> Forward Deployed Pruduct experience | C45: =E29 -> 0.15 | D45: =C45*180 -> 27 | E45: =IFERROR((IF($C$40="Gross Margin",F29/$F$37*$F$12,IF($C$40="Net Margin",F29/$F$37*$F$18,"Error")))/D45,"")/IF($D$40="USD",'Parámetros'!$L$3,1)/$C$10 -> 31.298905 | F45: =E45*D45 -> 845.07042
B46: =B30 -> Forward Deployed Enginnier | C46: =E30 | D46: =C46*180 -> 0 | E46: =IFERROR((IF($C$40="Gross Margin",F30/$F$37*$F$12,IF($C$40="Net Margin",F30/$F$37*$F$18,"Error")))/D46,"")/IF($D$40="USD",'Parámetros'!$L$3,1)/$C$10 -> 0 | F46: =E46*D46 -> 0
B47: =B31 | C47: =E31 | D47: =C47*180 -> 0 | E47: =IFERROR((IF($C$40="Gross Margin",F31/$F$37*$F$12,IF($C$40="Net Margin",F31/$F$37*$F$18,"Error")))/D47,"")/IF($D$40="USD",'Parámetros'!$L$3,1)/$C$10 -> 0 | F47: =E47*D47 -> 0
...

Sheet Equipo con UX
B2: Línea de Negocio | C2: Equipo Dedicado
B3: ¿Tipo de contrato vendedor? | C3: Deel/Ontop
B4: Comisión vendedor | C4: 0.05
B5: ¿Cuál es la fuente de tu lead? | C5: Directo
B6: Perfil Network | C6: Perfil Sr.
B7: ¿Pago con TC? | C7: 0 | F7: Gross Margin Meta | G7: =VLOOKUP($C$2,'Parámetros'!$A$118:$D$124,3,0) -> 0.4
B8: Factoring | C8: 0 | F8: =IF(D13>=G7,"Dentro del margen","¡Por debajo del margen!") -> ¡Por debajo del margen!
B9: Tecnologia
B10: Tiempo Duración: Mes | C10: 4
F11: COP | G11: USD
B12: Jugar con Gross Margin | C12: Comisión Venta | D12: =F12*C4+IFS(C5="Cold Calling",2%*138.3522%,C5="Mercadeo",2%*101%,C5="Network - Cold Calling",2%*138.3522%,C5="Referido Imagine",5%*138.3522%,C5="Directo",0)*F12+ifs(AND(C6="Perfil Jr.",C2="Network"),200000,AND(C6="Perfil Sr.",C2="Network"),350000,AND(C2="Network",C6="Perfil Semi Senior"), 600000,C2="Proyecto",1,C2="Equipo dedicado",1,C2="Servidores",1,C2="Enterprise",1,C2="Descubrimiento",1) -> 4032259.1 | E12: Precio Total | F12: =((C61+C57+C59)/((1-D13-'Parámetros'!L8*C7)))*IF(C8=1,102.4%,1) -> 80645161 | G12: =F12/'Parámetros'!$L$3 -> 22716.947 | I12: 160 | J12: 1
C13: Gross Margin | D13: 0.38 | E13: Precio mensual | F13: =F12/C10 -> 20161290 | G13: =F13/'Parámetros'!$L$3 -> 5679.2367 | I13: 12 | J13: =I13*J12/I12 -> 0.075
C14: ICA | D14: =F12*'Parámetros'!L5 -> 556451.61 | E14: Precio/Horas | F14: =F12/SUM(D43:D52)/C10 -> 62226.205 | G14: =G12/SUM(D43:D52)/C10 -> 17.528508
C15: NET Margin | D15: =(F12-C62-D14-D12-C7*'Parámetros'!L8*F12-IF(C8=1,2.4%,0)*F12)/F12 -> 0.10878894 | I15: 12 horas | J15: 3127889.9
I16: 20 horas | J16: 5044796.6
B18: Jugar con Net Margin | C18: Comisión Venta | D18: =F18*C4+IFS(C5="Cold Calling",2%*138.3522%,C5="Mercadeo",2%*101%,C5="Network - Cold Calling",2%*138.3522%,C5="Referido Imagine",5%*138.3522%,C5="Directo",0)*F18 -> 4527193.5 | E18: Precio Total | F18: =+C62/((1-IFS(C5="Cold Calling",2%*138.3522%,C5="Mercadeo",2%*101%,C5="Network - Cold Calling",2%*138.3522%,C5="Referido Imagine",5%*138.3522%,C5="Directo",0)-C4-D19-'Parámetros'!L5-C7*'Parámetros'!L8))*IF(C8=1,102.4%,1) -> 90543869 | G18: =F18/'Parámetros'!L3 -> 25505.315
C19: NET Margin | D19: 0.2 | E19: Precio mensual | F19: =F18/C10 -> 22635967 | G19: =G18/C10 -> 6376.3288
C20: ICA | D20: =F18*'Parámetros'!L5 -> 624752.7 | E20: Precio/Horas | F20: =F18/SUM(D43:D52)/C10 -> 69864.096 | G20: =G18/SUM(D43:D52)/C10 -> 19.680027
C21: Gross Margin | D21: =(((F18-C57-C59-C61-C7*'Parámetros'!L8*F18)-IF(C8=1,2.4%,0)*F18)/F18) -> 0.4477815
B23: ='Parámetros'!B149 -> Considerar como mínimo por cada Dev: PM:33%, QA:20%, Diseño:10%
E25: =SUM(E27:E34) -> 1.8
B26: Equipo | C26: Salario Base | D26: Tipo Contrato | E26: Dedicación | F26: Costo mensual | G26: Costo total | H26: % Tiempo Equipo
A27: =IFERROR(__xludf.DUMMYFUNCTION("COUNTIF(SPLIT(B27,"" ""),""Developer"")"),0.0) -> 0 | B27: Forward Deployed Pruduct experience | C27: =IFERROR(VLOOKUP(B27,'Parámetros'!A$1:B113,2, FALSE),"") -> 5000000 | D27: P. Servicios | E27: 0.5 | F27: =+IFERROR(IF(D27="Nómina",C27*1.38352,C27),"")*E27 -> 2500000 | G27: =F27*C$10 -> 10000000 | H27: =F27/(AVERAGE('Parámetros'!$F$5:$F$6)+$F$37) -> 0.0072159078
A28: =IFERROR(__xludf.DUMMYFUNCTION("COUNTIF(SPLIT(B28,"" ""),""Developer"")"),0.0) -> 0 | B28: Forward Deployed Enginnier | C28: =IFERROR(VLOOKUP(B28,'Parámetros'!A$1:B114,2, FALSE),"") -> 7000000 | D28: P. Servicios | E28: 1 | F28: =+IFERROR(IF(D28="Nómina",C28*1.38352,C28),"")*E28 -> 7000000 | G28: =F28*C$10 -> 28000000 | H28: =G28/(AVERAGE('Parámetros'!$F$5:$F$6)+$F$37) -> 0.080818167
A29: =IFERROR(__xludf.DUMMYFUNCTION("COUNTIF(SPLIT(B29,"" ""),""Developer"")"),0.0) -> 0 | B29: Tech Leald Orchestaror | C29: =IFERROR(VLOOKUP(B29,'Parámetros'!A$1:B115,2, FALSE),"") -> 10000000 | D29: P. Servicios | E29: 0.3 | F29: =+IFERROR(IF(D29="Nómina",C29*1.38352,C29),"")*E29 -> 3000000 | G29: =F29*C$10 -> 12000000 | H29: =G29/(AVERAGE('Parámetros'!$F$5:$F$6)+$F$37) -> 0.034636357
A30: =IFERROR(__xludf.DUMMYFUNCTION("COUNTIF(SPLIT(B30,"" ""),""Developer"")"),0.0) -> 0 | C30: =IFERROR(VLOOKUP(B30,'Parámetros'!A$1:B116,2, FALSE),"") | F30: =+IFERROR(IF(D30="Nómina",C30*1.38352,C30),"")*E30*105% -> 0 | G30: =F30*C$10 -> 0 | H30: =G30/(AVERAGE('Parámetros'!$F$5:$F$6)+$F$37) -> 0
A31: =IFERROR(__xludf.DUMMYFUNCTION("COUNTIF(SPLIT(B31,"" ""),""Developer"")"),0.0) -> 0
A32: =IFERROR(__xludf.DUMMYFUNCTION("COUNTIF(SPLIT(B32,"" ""),""Developer"")"),0.0) -> 0 | F32: =+IFERROR(IF(D32="Nómina",C32*1.38352,C32),"")*E32*105% -> 0 | G32: =F32*C$10 -> 0 | H32: =G32/(AVERAGE('Parámetros'!$F$5:$F$6)+$F$37) -> 0
A33: =IFERROR(__xludf.DUMMYFUNCTION("COUNTIF(SPLIT(B33,"" ""),""Developer"")"),0.0) -> 0 | F33: =+IFERROR(IF(D33="Nómina",C33*1.38352,C33),"")*E33*105% -> 0 | G33: =F33*C$10 -> 0 | H33: =G33/(AVERAGE('Parámetros'!$F$5:$F$6)+$F$37) -> 0
A34: =IFERROR(__xludf.DUMMYFUNCTION("COUNTIF(SPLIT(B34,"" ""),""Developer"")"),0.0) -> 0 | C34: =IFERROR(VLOOKUP(B34,'Parámetros'!A$1:B120,2, FALSE),"") | F34: =+IFERROR(IF(D34="Nómina",C34*1.38352,C34),"")*E34*105% -> 0 | G34: =F34*C$10 -> 0 | H34: =G34/(AVERAGE('Parámetros'!$F$5:$F$6)+$F$37) -> 0
C35: =IFERROR(VLOOKUP(B35,'Parámetros'!A$1:B121,2, FALSE),"") | F35: =+IFERROR(IF(D35="Nómina",C35*1.38352,C35),"")*E35*105% -> 0 | G35: =F35*C$10 -> 0 | H35: =G35/(AVERAGE('Parámetros'!$F$5:$F$6)+$F$37) -> 0
C36: =IFERROR(VLOOKUP(B36,'Parámetros'!A$1:B122,2, FALSE),"") | F36: =+IFERROR(IF(D36="Nómina",C36*1.38352,C36),"")*E36*105% -> 0 | G36: =F36*C$10 -> 0 | H36: =G36/(AVERAGE('Parámetros'!$F$5:$F$6)+$F$37) -> 0
F37: =SUM(F27:F36) -> 12500000 | G37: =SUM(G27:G36) -> 50000000 | H37: =SUM(H27:H36) -> 0.12267043
C40: Gross Margin | D40: USD
B42: Equipo | C42: Dedicación | D42: Capacidad Horas | E42: Precio x Hora | F42: Precio Total
B43: =B27 -> Forward Deployed Pruduct experience | C43: =E27 -> 0.5 | D43: =C43*180 -> 90 | E43: =IFERROR((IF($C$40="Gross Margin",F27/$F$37*$F$12,IF($C$40="Net Margin",F27/$F$37*$F$18,"Error")))/D43,"")/IF($D$40="USD",'Parámetros'!$L$3,1)/$C$10 -> 12.620526 | F43: =E43*D43 -> 1135.8473
B44: =B28 -> Forward Deployed Enginnier | C44: =E28 -> 1 | D44: =C44*180 -> 180 | E44: =IFERROR((IF($C$40="Gross Margin",F28/$F$37*$F$12,IF($C$40="Net Margin",F28/$F$37*$F$18,"Error")))/D44,"")/IF($D$40="USD",'Parámetros'!$L$3,1)/$C$10 -> 17.668736 | F44: =E44*D44 -> 3180.3726
B45: =B29 -> Tech Leald Orchestaror | C45: =E29 -> 0.3 | D45: =C45*180 -> 54 | E45: =IFERROR((IF($C$40="Gross Margin",F29/$F$37*$F$12,IF($C$40="Net Margin",F29/$F$37*$F$18,"Error")))/D45,"")/IF($D$40="USD",'Parámetros'!$L$3,1)/$C$10 -> 25.241052 | F45: =E45*D45 -> 1363.0168
B46: =B30 | C46: =E30 | D46: =C46*180 -> 0 | E46: =IFERROR((IF($C$40="Gross Margin",F30/$F$37*$F$12,IF($C$40="Net Margin",F30/$F$37*$F$18,"Error")))/D46,"")/IF($D$40="USD",'Parámetros'!$L$3,1)/$C$10 -> 0 | F46: =E46*D46 -> 0
B47: =B31 | C47: =E31 | D47: =C47*180 -> 0 | E47: =IFERROR((IF($C$40="Gross Margin",F31/$F$37*$F$12,IF($C$40="Net Margin",F31/$F$37*$F$18,"Error")))/D47,"")/IF($D$40="USD",'Parámetros'!$L$3,1)/$C$10 -> 0 | F47: =E47*D47 -> 0
...

Sheet Equipo UX + Pm
B2: Línea de Negocio | C2: Equipo Dedicado
B3: ¿Tipo de contrato vendedor? | C3: Deel/Ontop
B4: Comisión vendedor | C4: 0.05
B5: ¿Cuál es la fuente de tu lead? | C5: Directo
B6: Perfil Network | C6: Perfil Sr.
B7: ¿Pago con TC? | C7: 0 | F7: Gross Margin Meta | G7: =VLOOKUP($C$2,'Parámetros'!$A$118:$D$124,3,0) -> 0.4
B8: Factoring | C8: 0 | F8: =IF(D13>=G7,"Dentro del margen","¡Por debajo del margen!") -> ¡Por debajo del margen!
B9: Tecnologia
B10: Tiempo Duración: Mes | C10: 4
F11: COP | G11: USD
B12: Jugar con Gross Margin | C12: Comisión Venta | D12: =F12*C4+IFS(C5="Cold Calling",2%*138.3522%,C5="Mercadeo",2%*101%,C5="Network - Cold Calling",2%*138.3522%,C5="Referido Imagine",5%*138.3522%,C5="Directo",0)*F12+ifs(AND(C6="Perfil Jr.",C2="Network"),200000,AND(C6="Perfil Sr.",C2="Network"),350000,AND(C2="Network",C6="Perfil Semi Senior"), 600000,C2="Proyecto",1,C2="Equipo dedicado",1,C2="Servidores",1,C2="Enterprise",1,C2="Descubrimiento",1) -> 4370968.7 | E12: Precio Total | F12: =((C61+C57+C59)/((1-D13-'Parámetros'!L8*C7)))*IF(C8=1,102.4%,1) -> 87419355 | G12: =F12/'Parámetros'!$L$3 -> 24625.17 | I12: 160 | J12: 1
C13: Gross Margin | D13: 0.38 | E13: Precio mensual | F13: =F12/C10 -> 21854839 | G13: =F13/'Parámetros'!$L$3 -> 6156.2926 | I13: 12 | J13: =I13*J12/I12 -> 0.075
C14: ICA | D14: =F12*'Parámetros'!L5 -> 603193.55 | E14: Precio/Horas | F14: =F12/SUM(D43:D52)/C10 -> 60707.885 | G14: =G12/SUM(D43:D52)/C10 -> 17.100813
C15: NET Margin | D15: =(F12-C62-D14-D12-C7*'Parámetros'!L8*F12-IF(C8=1,2.4%,0)*F12)/F12 -> 0.10651467 | I15: 12 horas | J15: 3127889.9
I16: 20 horas | J16: 5044796.6
B18: Jugar con Net Margin | C18: Comisión Venta | D18: =F18*C4+IFS(C5="Cold Calling",2%*138.3522%,C5="Mercadeo",2%*101%,C5="Network - Cold Calling",2%*138.3522%,C5="Referido Imagine",5%*138.3522%,C5="Directo",0)*F18 -> 4920855.1 | E18: Precio Total | F18: =+C62/((1-IFS(C5="Cold Calling",2%*138.3522%,C5="Mercadeo",2%*101%,C5="Network - Cold Calling",2%*138.3522%,C5="Referido Imagine",5%*138.3522%,C5="Directo",0)-C4-D19-'Parámetros'!L5-C7*'Parámetros'!L8))*IF(C8=1,102.4%,1) -> 98417102 | G18: =F18/'Parámetros'!L3 -> 27723.127
C19: NET Margin | D19: 0.2 | E19: Precio mensual | F19: =F18/C10 -> 24604276 | G19: =G18/C10 -> 6930.7819
C20: ICA | D20: =F18*'Parámetros'!L5 -> 679078.01 | E20: Precio/Horas | F20: =F18/SUM(D43:D52)/C10 -> 68345.21 | G20: =G18/SUM(D43:D52)/C10 -> 19.252172
C21: Gross Margin | D21: =(((F18-C57-C59-C61-C7*'Parámetros'!L8*F18)-IF(C8=1,2.4%,0)*F18)/F18) -> 0.44928271
B23: ='Parámetros'!B149 -> Considerar como mínimo por cada Dev: PM:33%, QA:20%, Diseño:10%
E25: =SUM(E27:E34) -> 2
B26: Equipo | C26: Salario Base | D26: Tipo Contrato | E26: Dedicación | F26: Costo mensual | G26: Costo total | H26: % Tiempo Equipo
A27: =IFERROR(__xludf.DUMMYFUNCTION("COUNTIF(SPLIT(B27,"" ""),""Developer"")"),0.0) -> 0 | B27: Forward Deployed Pruduct experience | C27: =IFERROR(VLOOKUP(B27,'Parámetros'!A$1:B113,2, FALSE),"") -> 5000000 | D27: P. Servicios | E27: 0.5 | F27: =+IFERROR(IF(D27="Nómina",C27*1.38352,C27),"")*E27 -> 2500000 | G27: =F27*C$10 -> 10000000 | H27: =F27/(AVERAGE('Parámetros'!$F$5:$F$6)+$F$37) -> 0.0071941047
A28: =IFERROR(__xludf.DUMMYFUNCTION("COUNTIF(SPLIT(B28,"" ""),""Developer"")"),0.0) -> 0 | B28: Forward Deployed Enginnier | C28: =IFERROR(VLOOKUP(B28,'Parámetros'!A$1:B114,2, FALSE),"") -> 7000000 | D28: P. Servicios | E28: 1 | F28: =+IFERROR(IF(D28="Nómina",C28*1.38352,C28),"")*E28 -> 7000000 | G28: =F28*C$10 -> 28000000 | H28: =G28/(AVERAGE('Parámetros'!$F$5:$F$6)+$F$37) -> 0.080573973
A29: =IFERROR(__xludf.DUMMYFUNCTION("COUNTIF(SPLIT(B29,"" ""),""Developer"")"),0.0) -> 0 | B29: Tech Leald Orchestaror | C29: =IFERROR(VLOOKUP(B29,'Parámetros'!A$1:B115,2, FALSE),"") -> 10000000 | D29: P. Servicios | E29: 0.3 | F29: =+IFERROR(IF(D29="Nómina",C29*1.38352,C29),"")*E29 -> 3000000 | G29: =F29*C$10 -> 12000000 | H29: =G29/(AVERAGE('Parámetros'!$F$5:$F$6)+$F$37) -> 0.034531703
A30: =IFERROR(__xludf.DUMMYFUNCTION("COUNTIF(SPLIT(B30,"" ""),""Developer"")"),0.0) -> 0 | B30: Forward Deployed Product manager | C30: =IFERROR(VLOOKUP(B30,'Parámetros'!A$1:B116,2, FALSE),"") -> 5000000 | D30: P. Servicios | E30: 0.2 | F30: =+IFERROR(IF(D30="Nómina",C30*1.38352,C30),"")*E30*105% -> 1050000 | G30: =F30*C$10 -> 4200000 | H30: =G30/(AVERAGE('Parámetros'!$F$5:$F$6)+$F$37) -> 0.012086096
A31: =IFERROR(__xludf.DUMMYFUNCTION("COUNTIF(SPLIT(B31,"" ""),""Developer"")"),0.0) -> 0
A32: =IFERROR(__xludf.DUMMYFUNCTION("COUNTIF(SPLIT(B32,"" ""),""Developer"")"),0.0) -> 0 | F32: =+IFERROR(IF(D32="Nómina",C32*1.38352,C32),"")*E32*105% -> 0 | G32: =F32*C$10 -> 0 | H32: =G32/(AVERAGE('Parámetros'!$F$5:$F$6)+$F$37) -> 0
A33: =IFERROR(__xludf.DUMMYFUNCTION("COUNTIF(SPLIT(B33,"" ""),""Developer"")"),0.0) -> 0 | F33: =+IFERROR(IF(D33="Nómina",C33*1.38352,C33),"")*E33*105% -> 0 | G33: =F33*C$10 -> 0 | H33: =G33/(AVERAGE('Parámetros'!$F$5:$F$6)+$F$37) -> 0
A34: =IFERROR(__xludf.DUMMYFUNCTION("COUNTIF(SPLIT(B34,"" ""),""Developer"")"),0.0) -> 0 | C34: =IFERROR(VLOOKUP(B34,'Parámetros'!A$1:B120,2, FALSE),"") | F34: =+IFERROR(IF(D34="Nómina",C34*1.38352,C34),"")*E34*105% -> 0 | G34: =F34*C$10 -> 0 | H34: =G34/(AVERAGE('Parámetros'!$F$5:$F$6)+$F$37) -> 0
C35: =IFERROR(VLOOKUP(B35,'Parámetros'!A$1:B121,2, FALSE),"") | F35: =+IFERROR(IF(D35="Nómina",C35*1.38352,C35),"")*E35*105% -> 0 | G35: =F35*C$10 -> 0 | H35: =G35/(AVERAGE('Parámetros'!$F$5:$F$6)+$F$37) -> 0
C36: =IFERROR(VLOOKUP(B36,'Parámetros'!A$1:B122,2, FALSE),"") | F36: =+IFERROR(IF(D36="Nómina",C36*1.38352,C36),"")*E36*105% -> 0 | G36: =F36*C$10 -> 0 | H36: =G36/(AVERAGE('Parámetros'!$F$5:$F$6)+$F$37) -> 0
F37: =SUM(F27:F36) -> 13550000 | G37: =SUM(G27:G36) -> 54200000 | H37: =SUM(H27:H36) -> 0.13438588
C40: Gross Margin | D40: USD
B42: Equipo | C42: Dedicación | D42: Capacidad Horas | E42: Precio x Hora | F42: Precio Total
B43: =B27 -> Forward Deployed Pruduct experience | C43: =E27 -> 0.5 | D43: =C43*180 -> 90 | E43: =IFERROR((IF($C$40="Gross Margin",F27/$F$37*$F$12,IF($C$40="Net Margin",F27/$F$37*$F$18,"Error")))/D43,"")/IF($D$40="USD",'Parámetros'!$L$3,1)/$C$10 -> 12.620526 | F43: =E43*D43 -> 1135.8473
B44: =B28 -> Forward Deployed Enginnier | C44: =E28 -> 1 | D44: =C44*180 -> 180 | E44: =IFERROR((IF($C$40="Gross Margin",F28/$F$37*$F$12,IF($C$40="Net Margin",F28/$F$37*$F$18,"Error")))/D44,"")/IF($D$40="USD",'Parámetros'!$L$3,1)/$C$10 -> 17.668736 | F44: =E44*D44 -> 3180.3726
B45: =B29 -> Tech Leald Orchestaror | C45: =E29 -> 0.3 | D45: =C45*180 -> 54 | E45: =IFERROR((IF($C$40="Gross Margin",F29/$F$37*$F$12,IF($C$40="Net Margin",F29/$F$37*$F$18,"Error")))/D45,"")/IF($D$40="USD",'Parámetros'!$L$3,1)/$C$10 -> 25.241052 | F45: =E45*D45 -> 1363.0168
B46: =B30 -> Forward Deployed Product manager | C46: =E30 -> 0.2 | D46: =C46*180 -> 36 | E46: =IFERROR((IF($C$40="Gross Margin",F30/$F$37*$F$12,IF($C$40="Net Margin",F30/$F$37*$F$18,"Error")))/D46,"")/IF($D$40="USD",'Parámetros'!$L$3,1)/$C$10 -> 13.251552 | F46: =E46*D46 -> 477.05588
B47: =B31 | C47: =E31 | D47: =C47*180 -> 0 | E47: =IFERROR((IF($C$40="Gross Margin",F31/$F$37*$F$12,IF($C$40="Net Margin",F31/$F$37*$F$18,"Error")))/D47,"")/IF($D$40="USD",'Parámetros'!$L$3,1)/$C$10 -> 0 | F47: =E47*D47 -> 0
...

Sheet Equipo dos FDE
B2: Línea de Negocio | C2: Equipo Dedicado
B3: ¿Tipo de contrato vendedor? | C3: Deel/Ontop
B4: Comisión vendedor | C4: 0.05
B5: ¿Cuál es la fuente de tu lead? | C5: Directo
B6: Perfil Network | C6: Perfil Sr.
B7: ¿Pago con TC? | C7: 0 | F7: Gross Margin Meta | G7: =VLOOKUP($C$2,'Parámetros'!$A$118:$D$124,3,0) -> 0.4
B8: Factoring | C8: 0 | F8: =IF(D13>=G7,"Dentro del margen","¡Por debajo del margen!") -> ¡Por debajo del margen!
B9: Tecnologia
B10: Tiempo Duración: Mes | C10: 4
F11: COP | G11: USD
B12: Jugar con Gross Margin | C12: Comisión Venta | D12: =F12*C4+IFS(C5="Cold Calling",2%*138.3522%,C5="Mercadeo",2%*101%,C5="Network - Cold Calling",2%*138.3522%,C5="Referido Imagine",5%*138.3522%,C5="Directo",0)*F12+ifs(AND(C6="Perfil Jr.",C2="Network"),200000,AND(C6="Perfil Sr.",C2="Network"),350000,AND(C2="Network",C6="Perfil Semi Senior"), 600000,C2="Proyecto",1,C2="Equipo dedicado",1,C2="Servidores",1,C2="Enterprise",1,C2="Descubrimiento",1) -> 6629033.3 | E12: Precio Total | F12: =((C61+C57+C59)/((1-D13-'Parámetros'!L8*C7)))*IF(C8=1,102.4%,1) -> 1.3258065e+08 | G12: =F12/'Parámetros'!$L$3 -> 37346.661 | I12: 160 | J12: 1
C13: Gross Margin | D13: 0.38 | E13: Precio mensual | F13: =F12/C10 -> 33145161 | G13: =F13/'Parámetros'!$L$3 -> 9336.6652 | I13: 12 | J13: =I13*J12/I12 -> 0.075
C14: ICA | D14: =F12*'Parámetros'!L5 -> 914806.45 | E14: Precio/Horas | F14: =F12/SUM(D43:D52)/C10 -> 61379.928 | G14: =G12/SUM(D43:D52)/C10 -> 17.290121
C15: NET Margin | D15: =(F12-C62-D14-D12-C7*'Parámetros'!L8*F12-IF(C8=1,2.4%,0)*F12)/F12 -> 0.099176871 | I15: 12 horas | J15: 3127889.9
I16: 20 horas | J16: 5044796.6
B18: Jugar con Net Margin | C18: Comisión Venta | D18: =F18*C4+IFS(C5="Cold Calling",2%*138.3522%,C5="Mercadeo",2%*101%,C5="Network - Cold Calling",2%*138.3522%,C5="Referido Imagine",5%*138.3522%,C5="Directo",0)*F18 -> 7528453.2 | E18: Precio Total | F18: =+C62/((1-IFS(C5="Cold Calling",2%*138.3522%,C5="Mercadeo",2%*101%,C5="Network - Cold Calling",2%*138.3522%,C5="Referido Imagine",5%*138.3522%,C5="Directo",0)-C4-D19-'Parámetros'!L5-C7*'Parámetros'!L8))*IF(C8=1,102.4%,1) -> 1.5056906e+08 | G18: =F18/'Parámetros'!L3 -> 42413.821
C19: NET Margin | D19: 0.2 | E19: Precio mensual | F19: =F18/C10 -> 37642266 | G19: =G18/C10 -> 10603.455
C20: ICA | D20: =F18*'Parámetros'!L5 -> 1038926.5 | E20: Precio/Horas | F20: =F18/SUM(D43:D52)/C10 -> 69707.9 | G20: =G18/SUM(D43:D52)/C10 -> 19.636028
C21: Gross Margin | D21: =(((F18-C57-C59-C61-C7*'Parámetros'!L8*F18)-IF(C8=1,2.4%,0)*F18)/F18) -> 0.45407113
B23: ='Parámetros'!B149 -> Considerar como mínimo por cada Dev: PM:33%, QA:20%, Diseño:10%
E25: =SUM(E27:E34) -> 3
B26: Equipo | C26: Salario Base | D26: Tipo Contrato | E26: Dedicación | F26: Costo mensual | G26: Costo total | H26: % Tiempo Equipo
A27: =IFERROR(__xludf.DUMMYFUNCTION("COUNTIF(SPLIT(B27,"" ""),""Developer"")"),0.0) -> 0 | B27: Forward Deployed Pruduct experience | C27: =IFERROR(VLOOKUP(B27,'Parámetros'!A$1:B113,2, FALSE),"") -> 5000000 | D27: P. Servicios | E27: 0.5 | F27: =+IFERROR(IF(D27="Nómina",C27*1.38352,C27),"")*E27 -> 2500000 | G27: =F27*C$10 -> 10000000 | H27: =F27/(AVERAGE('Parámetros'!$F$5:$F$6)+$F$37) -> 0.0070520518
A28: =IFERROR(__xludf.DUMMYFUNCTION("COUNTIF(SPLIT(B28,"" ""),""Developer"")"),0.0) -> 0 | B28: Forward Deployed Enginnier | C28: =IFERROR(VLOOKUP(B28,'Parámetros'!A$1:B114,2, FALSE),"") -> 7000000 | D28: P. Servicios | E28: 1 | F28: =+IFERROR(IF(D28="Nómina",C28*1.38352,C28),"")*E28 -> 7000000 | G28: =F28*C$10 -> 28000000 | H28: =G28/(AVERAGE('Parámetros'!$F$5:$F$6)+$F$37) -> 0.07898298
A29: =IFERROR(__xludf.DUMMYFUNCTION("COUNTIF(SPLIT(B29,"" ""),""Developer"")"),0.0) -> 0 | B29: Tech Leald Orchestaror | C29: =IFERROR(VLOOKUP(B29,'Parámetros'!A$1:B115,2, FALSE),"") -> 10000000 | D29: P. Servicios | E29: 0.3 | F29: =+IFERROR(IF(D29="Nómina",C29*1.38352,C29),"")*E29 -> 3000000 | G29: =F29*C$10 -> 12000000 | H29: =G29/(AVERAGE('Parámetros'!$F$5:$F$6)+$F$37) -> 0.033849849
A30: =IFERROR(__xludf.DUMMYFUNCTION("COUNTIF(SPLIT(B30,"" ""),""Developer"")"),0.0) -> 0 | B30: Forward Deployed Product manager | C30: =IFERROR(VLOOKUP(B30,'Parámetros'!A$1:B116,2, FALSE),"") -> 5000000 | D30: P. Servicios | E30: 0.2 | F30: =+IFERROR(IF(D30="Nómina",C30*1.38352,C30),"")*E30*105% -> 1050000 | G30: =F30*C$10 -> 4200000 | H30: =G30/(AVERAGE('Parámetros'!$F$5:$F$6)+$F$37) -> 0.011847447
A31: =IFERROR(__xludf.DUMMYFUNCTION("COUNTIF(SPLIT(B31,"" ""),""Developer"")"),0.0) -> 0 | B31: Forward Deployed Enginnier | C31: =IFERROR(VLOOKUP(B31,'Parámetros'!A$1:B117,2, FALSE),"") -> 7000000 | D31: P. Servicios | E31: 1 | F31: =+IFERROR(IF(D31="Nómina",C31*1.38352,C31),"")*E31 -> 7000000 | G31: =F31*C$10 -> 28000000 | H31: =G31/(AVERAGE('Parámetros'!$F$5:$F$6)+$F$37) -> 0.07898298
A32: =IFERROR(__xludf.DUMMYFUNCTION("COUNTIF(SPLIT(B32,"" ""),""Developer"")"),0.0) -> 0 | F32: =+IFERROR(IF(D32="Nómina",C32*1.38352,C32),"")*E32*105% -> 0 | G32: =F32*C$10 -> 0 | H32: =G32/(AVERAGE('Parámetros'!$F$5:$F$6)+$F$37) -> 0
A33: =IFERROR(__xludf.DUMMYFUNCTION("COUNTIF(SPLIT(B33,"" ""),""Developer"")"),0.0) -> 0 | F33: =+IFERROR(IF(D33="Nómina",C33*1.38352,C33),"")*E33*105% -> 0 | G33: =F33*C$10 -> 0 | H33: =G33/(AVERAGE('Parámetros'!$F$5:$F$6)+$F$37) -> 0
A34: =IFERROR(__xludf.DUMMYFUNCTION("COUNTIF(SPLIT(B34,"" ""),""Developer"")"),0.0) -> 0 | C34: =IFERROR(VLOOKUP(B34,'Parámetros'!A$1:B120,2, FALSE),"") | F34: =+IFERROR(IF(D34="Nómina",C34*1.38352,C34),"")*E34*105% -> 0 | G34: =F34*C$10 -> 0 | H34: =G34/(AVERAGE('Parámetros'!$F$5:$F$6)+$F$37) -> 0
C35: =IFERROR(VLOOKUP(B35,'Parámetros'!A$1:B121,2, FALSE),"") | F35: =+IFERROR(IF(D35="Nómina",C35*1.38352,C35),"")*E35*105% -> 0 | G35: =F35*C$10 -> 0 | H35: =G35/(AVERAGE('Parámetros'!$F$5:$F$6)+$F$37) -> 0
C36: =IFERROR(VLOOKUP(B36,'Parámetros'!A$1:B122,2, FALSE),"") | F36: =+IFERROR(IF(D36="Nómina",C36*1.38352,C36),"")*E36*105% -> 0 | G36: =F36*C$10 -> 0 | H36: =G36/(AVERAGE('Parámetros'!$F$5:$F$6)+$F$37) -> 0
F37: =SUM(F27:F36) -> 20550000 | G37: =SUM(G27:G36) -> 82200000 | H37: =SUM(H27:H36) -> 0.21071531
C40: Gross Margin | D40: USD
B42: Equipo | C42: Dedicación | D42: Capacidad Horas | E42: Precio x Hora | F42: Precio Total
B43: =B27 -> Forward Deployed Pruduct experience | C43: =E27 -> 0.5 | D43: =C43*180 -> 90 | E43: =IFERROR((IF($C$40="Gross Margin",F27/$F$37*$F$12,IF($C$40="Net Margin",F27/$F$37*$F$18,"Error")))/D43,"")/IF($D$40="USD",'Parámetros'!$L$3,1)/$C$10 -> 12.620526 | F43: =E43*D43 -> 1135.8473
B44: =B28 -> Forward Deployed Enginnier | C44: =E28 -> 1 | D44: =C44*180 -> 180 | E44: =IFERROR((IF($C$40="Gross Margin",F28/$F$37*$F$12,IF($C$40="Net Margin",F28/$F$37*$F$18,"Error")))/D44,"")/IF($D$40="USD",'Parámetros'!$L$3,1)/$C$10 -> 17.668736 | F44: =E44*D44 -> 3180.3726
B45: =B29 -> Tech Leald Orchestaror | C45: =E29 -> 0.3 | D45: =C45*180 -> 54 | E45: =IFERROR((IF($C$40="Gross Margin",F29/$F$37*$F$12,IF($C$40="Net Margin",F29/$F$37*$F$18,"Error")))/D45,"")/IF($D$40="USD",'Parámetros'!$L$3,1)/$C$10 -> 25.241052 | F45: =E45*D45 -> 1363.0168
B46: =B30 -> Forward Deployed Product manager | C46: =E30 -> 0.2 | D46: =C46*180 -> 36 | E46: =IFERROR((IF($C$40="Gross Margin",F30/$F$37*$F$12,IF($C$40="Net Margin",F30/$F$37*$F$18,"Error")))/D46,"")/IF($D$40="USD",'Parámetros'!$L$3,1)/$C$10 -> 13.251552 | F46: =E46*D46 -> 477.05588
B47: =B31 -> Forward Deployed Enginnier | C47: =E31 -> 1 | D47: =C47*180 -> 180 | E47: =IFERROR((IF($C$40="Gross Margin",F31/$F$37*$F$12,IF($C$40="Net Margin",F31/$F$37*$F$18,"Error")))/D47,"")/IF($D$40="USD",'Parámetros'!$L$3,1)/$C$10 -> 17.668736 | F47: =E47*D47 -> 3180.3726
...

Sheet Sprint MVP
B2: Línea de Negocio | C2: Descubrimiento
B3: ¿Tipo de contrato vendedor? | C3: Deel/Ontop
B4: Comisión vendedor | C4: 0.1
B5: ¿Cuál es la fuente de tu lead? | C5: Directo
B6: Perfil Network | C6: Perfil Sr.
B7: ¿Pago con TC? | C7: 0 | F7: Gross Margin Meta | G7: =VLOOKUP($C$2,'Parámetros'!$A$118:$D$124,3,0) -> 0.5
B8: Factoring | C8: 0 | F8: =IF(D13>=G7,"Dentro del margen","¡Por debajo del margen!") -> ¡Por debajo del margen!
B9: Tecnologia
B10: Tiempo Duración: Mes | C10: 1
F11: COP | G11: USD
B12: Jugar con Gross Margin | C12: Comisión Venta | D12: =F12*C4+IFS(C5="Cold Calling",2%*138.3522%,C5="Mercadeo",2%*101%,C5="Network - Cold Calling",2%*138.3522%,C5="Referido Imagine",5%*138.3522%,C5="Directo",0)*F12+ifs(AND(C6="Perfil Jr.",C2="Network"),200000,AND(C6="Perfil Sr.",C2="Network"),350000,AND(C2="Network",C6="Perfil Semi Senior"), 600000,C2="Proyecto",1,C2="Equipo dedicado",1,C2="Servidores",1,C2="Enterprise",1,C2="Descubrimiento",1) -> 2192983.5 | E12: Precio Total | F12: =((C61+C57+C59)/((1-D13-'Parámetros'!L8*C7)))*IF(C8=1,102.4%,1) -> 21929825 | G12: =F12/'Parámetros'!$L$3 -> 6177.4154 | I12: 160 | J12: 1
C13: Gross Margin | D13: 0.43 | E13: Precio mensual | F13: =F12/C10 -> 21929825 | G13: =F13/'Parámetros'!$L$3 -> 6177.4154 | I13: 12 | J13: =I13*J12/I12 -> 0.075
C14: ICA | D14: =F12*'Parámetros'!L5 -> 151315.79 | E14: Precio/Horas | F14: =F12/SUM(D43:D52)/C10 -> 81221.572 | G14: =G12/SUM(D43:D52)/C10 -> 22.879316
C15: NET Margin | D15: =(F12-C62-D14-D12-C7*'Parámetros'!L8*F12-IF(C8=1,2.4%,0)*F12)/F12 -> 0.091302425 | I15: 12 horas | J15: 3127889.9
I16: 20 horas | J16: 5044796.6
B18: Jugar con Net Margin | C18: Comisión Venta | D18: =F18*C4+IFS(C5="Cold Calling",2%*138.3522%,C5="Mercadeo",2%*101%,C5="Network - Cold Calling",2%*138.3522%,C5="Referido Imagine",5%*138.3522%,C5="Directo",0)*F18 -> 2536903.6 | E18: Precio Total | F18: =+C62/((1-IFS(C5="Cold Calling",2%*138.3522%,C5="Mercadeo",2%*101%,C5="Network - Cold Calling",2%*138.3522%,C5="Referido Imagine",5%*138.3522%,C5="Directo",0)-C4-D19-'Parámetros'!L5-C7*'Parámetros'!L8))*IF(C8=1,102.4%,1) -> 25369036 | G18: =F18/'Parámetros'!L3 -> 7146.2074
C19: NET Margin | D19: 0.2 | E19: Precio mensual | F19: =F18/C10 -> 25369036 | G19: =G18/C10 -> 7146.2074
C20: ICA | D20: =F18*'Parámetros'!L5 -> 175046.35 | E20: Precio/Horas | F20: =F18/SUM(D43:D52)/C10 -> 93959.394 | G20: =G18/SUM(D43:D52)/C10 -> 26.467435
C21: Gross Margin | D21: =(((F18-C57-C59-C61-C7*'Parámetros'!L8*F18)-IF(C8=1,2.4%,0)*F18)/F18) -> 0.50727336
B23: ='Parámetros'!B149 -> Considerar como mínimo por cada Dev: PM:33%, QA:20%, Diseño:10%
J24: dias | K24: 22 | L24: 100
E25: =SUM(E27:E34) -> 1.5 | J25: 5 | K25: =J25*L24/K24 -> 22.727273 | L25: 5729166.7
B26: Equipo | C26: Salario Base | D26: Tipo Contrato | E26: Dedicación | F26: Costo mensual | G26: Costo total | H26: % Tiempo Equipo | J26: 15 | K26: =J26*L24/K24 -> 68.181818 | L26: 14912281
A27: =IFERROR(__xludf.DUMMYFUNCTION("COUNTIF(SPLIT(B27,"" ""),""Developer"")"),0.0) -> 0 | B27: Forward Deployed Pruduct experience | C27: 5000000 | D27: P. Servicios | E27: 0.5 | F27: =+IFERROR(IF(D27="Nómina",C27*1.38352,C27),"")*E27 -> 2500000 | G27: =F27*C$10 -> 2500000 | H27: =F27/(AVERAGE('Parámetros'!$F$5:$F$6)+$F$37) -> 0.0072159078 | J27: 20 | K27: =J27*L24/K24 -> 90.909091 | L27: 21929825
A28: =IFERROR(__xludf.DUMMYFUNCTION("COUNTIF(SPLIT(B28,"" ""),""Developer"")"),0.0) -> 0 | B28: Forward Deployed Enginnier | C28: 10000000 | D28: P. Servicios | E28: 1 | F28: =+IFERROR(IF(D28="Nómina",C28*1.38352,C28),"")*E28 -> 10000000 | G28: =F28*C$10 -> 10000000 | H28: =G28/(AVERAGE('Parámetros'!$F$5:$F$6)+$F$37) -> 0.028863631
A29: =IFERROR(__xludf.DUMMYFUNCTION("COUNTIF(SPLIT(B29,"" ""),""Developer"")"),0.0) -> 0
A30: =IFERROR(__xludf.DUMMYFUNCTION("COUNTIF(SPLIT(B30,"" ""),""Developer"")"),0.0) -> 0
A31: =IFERROR(__xludf.DUMMYFUNCTION("COUNTIF(SPLIT(B31,"" ""),""Developer"")"),0.0) -> 0
A32: =IFERROR(__xludf.DUMMYFUNCTION("COUNTIF(SPLIT(B32,"" ""),""Developer"")"),0.0) -> 0 | F32: =+IFERROR(IF(D32="Nómina",C32*1.38352,C32),"")*E32*105% -> 0 | G32: =F32*C$10 -> 0 | H32: =G32/(AVERAGE('Parámetros'!$F$5:$F$6)+$F$37) -> 0
A33: =IFERROR(__xludf.DUMMYFUNCTION("COUNTIF(SPLIT(B33,"" ""),""Developer"")"),0.0) -> 0 | F33: =+IFERROR(IF(D33="Nómina",C33*1.38352,C33),"")*E33*105% -> 0 | G33: =F33*C$10 -> 0 | H33: =G33/(AVERAGE('Parámetros'!$F$5:$F$6)+$F$37) -> 0
A34: =IFERROR(__xludf.DUMMYFUNCTION("COUNTIF(SPLIT(B34,"" ""),""Developer"")"),0.0) -> 0 | C34: =IFERROR(VLOOKUP(B34,'Parámetros'!A$1:B120,2, FALSE),"") | F34: =+IFERROR(IF(D34="Nómina",C34*1.38352,C34),"")*E34*105% -> 0 | G34: =F34*C$10 -> 0 | H34: =G34/(AVERAGE('Parámetros'!$F$5:$F$6)+$F$37) -> 0
C35: =IFERROR(VLOOKUP(B35,'Parámetros'!A$1:B121,2, FALSE),"") | F35: =+IFERROR(IF(D35="Nómina",C35*1.38352,C35),"")*E35*105% -> 0 | G35: =F35*C$10 -> 0 | H35: =G35/(AVERAGE('Parámetros'!$F$5:$F$6)+$F$37) -> 0
C36: =IFERROR(VLOOKUP(B36,'Parámetros'!A$1:B122,2, FALSE),"") | F36: =+IFERROR(IF(D36="Nómina",C36*1.38352,C36),"")*E36*105% -> 0 | G36: =F36*C$10 -> 0 | H36: =G36/(AVERAGE('Parámetros'!$F$5:$F$6)+$F$37) -> 0
F37: =SUM(F27:F36) -> 12500000 | G37: =SUM(G27:G36) -> 12500000 | H37: =SUM(H27:H36) -> 0.036079539
C40: Gross Margin | D40: USD
B42: Equipo | C42: Dedicación | D42: Capacidad Horas | E42: Precio x Hora | F42: Precio Total
B43: =B27 -> Forward Deployed Pruduct experience | C43: =E27 -> 0.5 | D43: =C43*180 -> 90 | E43: =IFERROR((IF($C$40="Gross Margin",F27/$F$37*$F$12,IF($C$40="Net Margin",F27/$F$37*$F$18,"Error")))/D43,"")/IF($D$40="USD",'Parámetros'!$L$3,1)/$C$10 -> 13.72759 | F43: =E43*D43 -> 1235.4831
B44: =B28 -> Forward Deployed Enginnier | C44: =E28 -> 1 | D44: =C44*180 -> 180 | E44: =IFERROR((IF($C$40="Gross Margin",F28/$F$37*$F$12,IF($C$40="Net Margin",F28/$F$37*$F$18,"Error")))/D44,"")/IF($D$40="USD",'Parámetros'!$L$3,1)/$C$10 -> 27.455179 | F44: =E44*D44 -> 4941.9323
B45: =B29 | C45: =E29 | D45: =C45*180 -> 0 | E45: =IFERROR((IF($C$40="Gross Margin",F29/$F$37*$F$12,IF($C$40="Net Margin",F29/$F$37*$F$18,"Error")))/D45,"")/IF($D$40="USD",'Parámetros'!$L$3,1)/$C$10 -> 0 | F45: =E45*D45 -> 0
B46: =B30 | C46: =E30 | D46: =C46*180 -> 0 | E46: =IFERROR((IF($C$40="Gross Margin",F30/$F$37*$F$12,IF($C$40="Net Margin",F30/$F$37*$F$18,"Error")))/D46,"")/IF($D$40="USD",'Parámetros'!$L$3,1)/$C$10 -> 0 | F46: =E46*D46 -> 0
...

Sheet Copy of PRICING PLANTILLA  6
B2: Línea de Negocio | C2: Network
B3: ¿Tipo de contrato vendedor? | C3: Prestación de Servicios
B4: Comisión vendedor | C4: =Ifs(C5="Referido Imagine", VLOOKUP(C2,'Parámetros'!$A$118:$B$124,2,0)*IF(C3="Nómina",1.38522,IF(C3="Prestación de Servicios",1,102%))/2,C5="Network - Cold Calling",VLOOKUP(C2,'Parámetros'!$A$118:$B$124,2,0)*IF(C3="Nómina",1.38522,IF(C3="Prestación de Servicios",1,102%))-2%*138.352222%,C5="Mercadeo",VLOOKUP(C2,'Parámetros'!$A$118:$B$124,2,0)*IF(C3="Nómina",1.38522,IF(C3="Prestación de Servicios",1,102%)),C5="Cold Calling",VLOOKUP(C2,'Parámetros'!$A$118:$B$124,2,0)*IF(C3="Nómina",1.38522,IF(C3="Prestación de Servicios",1,102%)),C5="Directo",VLOOKUP(C2,'Parámetros'!$A$118:$B$124,2,0)*IF(C3="Nómina",1.38522,IF(C3="Prestación de Servicios",1,102%)))*IF(C2="Servidores ",0,1) -> 0.085
B5: ¿Cuál es la fuente de tu lead? | C5: Mercadeo
B6: Perfil Network | C6: Perfil Semi senior
B7: ¿Pago con TC? | C7: 0 | F7: Gross Margin Meta | G7: =VLOOKUP($C$2,'Parámetros'!$A$118:$D$124,3,0) -> 0.3
